[2020-06-15 17:27:46,815] [autoreload.py:598] [autoreload:run_with_reloader] [INFO]- Watching for file changes with StatReloader
[2020-06-15 17:27:51,623] [basehttp.py:157] [basehttp:log_message] [INFO]- "OPTIONS /token/ HTTP/1.1" 200 0
[2020-06-15 17:27:51,813] [basehttp.py:157] [basehttp:log_message] [INFO]- "POST /token/ HTTP/1.1" 200 469
[2020-06-15 17:27:51,858] [basehttp.py:157] [basehttp:log_message] [INFO]- "GET /system/user/info/ HTTP/1.1" 200 136
[2020-06-15 17:27:54,487] [basehttp.py:157] [basehttp:log_message] [INFO]- "GET /system/organization/ HTTP/1.1" 200 476
[2020-06-15 17:27:54,497] [basehttp.py:157] [basehttp:log_message] [INFO]- "GET /system/role/ HTTP/1.1" 200 232
[2020-06-15 17:27:54,498] [basehttp.py:157] [basehttp:log_message] [INFO]- "GET /system/user/?page=1&page_size=20 HTTP/1.1" 200 527
[2020-06-15 17:27:56,288] [basehttp.py:157] [basehttp:log_message] [INFO]- "GET /system/organization/ HTTP/1.1" 200 476
[2020-06-15 17:27:58,000] [basehttp.py:157] [basehttp:log_message] [INFO]- "GET /system/organization/ HTTP/1.1" 200 476
[2020-06-15 17:27:58,001] [basehttp.py:157] [basehttp:log_message] [INFO]- "GET /system/permission/ HTTP/1.1" 200 5844
[2020-06-15 17:27:58,002] [basehttp.py:157] [basehttp:log_message] [INFO]- "GET /system/role/ HTTP/1.1" 200 232
[2020-06-15 17:28:10,097] [basehttp.py:157] [basehttp:log_message] [INFO]- "OPTIONS /system/position/ HTTP/1.1" 200 0
[2020-06-15 17:28:10,170] [basehttp.py:157] [basehttp:log_message] [INFO]- "GET /system/position/ HTTP/1.1" 200 33
[2020-06-15 17:28:11,798] [basehttp.py:157] [basehttp:log_message] [INFO]- "GET /system/dicttype/ HTTP/1.1" 200 187
[2020-06-15 17:28:13,610] [basehttp.py:157] [basehttp:log_message] [INFO]- "OPTIONS /system/dict/?page=1&page_size=20&type=1 HTTP/1.1" 200 0
[2020-06-15 17:28:13,857] [log.py:228] [log:log_response] [ERROR]- Internal Server Error: /system/dict/
Traceback (most recent call last):
  File "E:\cnas\server\venv\lib\site-packages\django\db\backends\utils.py", line 86, in _execute
    return self.cursor.execute(sql, params)
  File "E:\cnas\server\venv\lib\site-packages\django\db\backends\sqlite3\base.py", line 396, in execute
    return Database.Cursor.execute(self, query, params)
sqlite3.OperationalError: no such column: system_dict.other

The above exception was the direct cause of the following exception:

Traceback (most recent call last):
  File "E:\cnas\server\venv\lib\site-packages\django\core\handlers\exception.py", line 34, in inner
    response = get_response(request)
  File "E:\cnas\server\venv\lib\site-packages\django\core\handlers\base.py", line 115, in _get_response
    response = self.process_exception_by_middleware(e, request)
  File "E:\cnas\server\venv\lib\site-packages\django\core\handlers\base.py", line 113, in _get_response
    response = wrapped_callback(request, *callback_args, **callback_kwargs)
  File "E:\cnas\server\venv\lib\site-packages\django\views\decorators\csrf.py", line 54, in wrapped_view
    return view_func(*args, **kwargs)
  File "E:\cnas\server\venv\lib\site-packages\rest_framework\viewsets.py", line 114, in view
    return self.dispatch(request, *args, **kwargs)
  File "E:\cnas\server\venv\lib\site-packages\rest_framework\views.py", line 505, in dispatch
    response = self.handle_exception(exc)
  File "E:\cnas\server\venv\lib\site-packages\rest_framework\views.py", line 465, in handle_exception
    self.raise_uncaught_exception(exc)
  File "E:\cnas\server\venv\lib\site-packages\rest_framework\views.py", line 476, in raise_uncaught_exception
    raise exc
  File "E:\cnas\server\venv\lib\site-packages\rest_framework\views.py", line 502, in dispatch
    response = handler(request, *args, **kwargs)
  File "E:\cnas\server\venv\lib\site-packages\rest_framework\mixins.py", line 46, in list
    return Response(serializer.data)
  File "E:\cnas\server\venv\lib\site-packages\rest_framework\serializers.py", line 760, in data
    ret = super().data
  File "E:\cnas\server\venv\lib\site-packages\rest_framework\serializers.py", line 260, in data
    self._data = self.to_representation(self.instance)
  File "E:\cnas\server\venv\lib\site-packages\rest_framework\serializers.py", line 678, in to_representation
    self.child.to_representation(item) for item in iterable
  File "E:\cnas\server\venv\lib\site-packages\django\db\models\query.py", line 276, in __iter__
    self._fetch_all()
  File "E:\cnas\server\venv\lib\site-packages\django\db\models\query.py", line 1261, in _fetch_all
    self._result_cache = list(self._iterable_class(self))
  File "E:\cnas\server\venv\lib\site-packages\django\db\models\query.py", line 57, in __iter__
    results = compiler.execute_sql(chunked_fetch=self.chunked_fetch, chunk_size=self.chunk_size)
  File "E:\cnas\server\venv\lib\site-packages\django\db\models\sql\compiler.py", line 1152, in execute_sql
    cursor.execute(sql, params)
  File "E:\cnas\server\venv\lib\site-packages\django\db\backends\utils.py", line 100, in execute
    return super().execute(sql, params)
  File "E:\cnas\server\venv\lib\site-packages\django\db\backends\utils.py", line 68, in execute
    return self._execute_with_wrappers(sql, params, many=False, executor=self._execute)
  File "E:\cnas\server\venv\lib\site-packages\django\db\backends\utils.py", line 77, in _execute_with_wrappers
    return executor(sql, params, many, context)
  File "E:\cnas\server\venv\lib\site-packages\django\db\backends\utils.py", line 86, in _execute
    return self.cursor.execute(sql, params)
  File "E:\cnas\server\venv\lib\site-packages\django\db\utils.py", line 90, in __exit__
    raise dj_exc_value.with_traceback(traceback) from exc_value
  File "E:\cnas\server\venv\lib\site-packages\django\db\backends\utils.py", line 86, in _execute
    return self.cursor.execute(sql, params)
  File "E:\cnas\server\venv\lib\site-packages\django\db\backends\sqlite3\base.py", line 396, in execute
    return Database.Cursor.execute(self, query, params)
django.db.utils.OperationalError: no such column: system_dict.other
[2020-06-15 17:28:13,877] [basehttp.py:157] [basehttp:log_message] [ERROR]- "GET /system/dict/?page=1&page_size=20&type=1 HTTP/1.1" 500 22908
[2020-06-15 17:28:52,473] [autoreload.py:598] [autoreload:run_with_reloader] [INFO]- Watching for file changes with StatReloader
[2020-06-15 17:29:19,996] [basehttp.py:157] [basehttp:log_message] [INFO]- "GET /system/dict/?page=1&page_size=20&type=1 HTTP/1.1" 200 33
[2020-06-15 17:29:21,958] [basehttp.py:157] [basehttp:log_message] [INFO]- "OPTIONS /file/?page=1&page_size=20 HTTP/1.1" 200 0
[2020-06-15 17:29:21,988] [basehttp.py:157] [basehttp:log_message] [INFO]- "GET /file/?page=1&page_size=20 HTTP/1.1" 200 83
[2020-06-15 17:29:23,341] [basehttp.py:157] [basehttp:log_message] [INFO]- "OPTIONS /system/task/?page=1&page_size=20 HTTP/1.1" 200 0
[2020-06-15 17:29:23,355] [basehttp.py:157] [basehttp:log_message] [INFO]- "GET /system/task/?page=1&page_size=20 HTTP/1.1" 200 83
[2020-06-15 17:29:25,961] [basehttp.py:157] [basehttp:log_message] [INFO]- "GET /system/permission/ HTTP/1.1" 200 5844
[2020-06-15 17:29:29,205] [basehttp.py:157] [basehttp:log_message] [INFO]- "GET /system/organization/ HTTP/1.1" 200 476
[2020-06-15 17:29:29,217] [basehttp.py:157] [basehttp:log_message] [INFO]- "GET /system/user/?page=1&page_size=20 HTTP/1.1" 200 527
[2020-06-15 17:29:29,226] [basehttp.py:157] [basehttp:log_message] [INFO]- "GET /system/role/ HTTP/1.1" 200 232
